<?xml version="1.0"?> 
<sdf version='1.6'>
  <world name='default'>
    <include>
      <uri>model://sun</uri>
    </include>

    <include>
      <uri>model://ground_plane</uri>
    </include>
    <model name='pendulum_cart'>
    	<static>false</static>
      <link name='cart_body'>
        <pose frame=''>0 0 0.1 0 -0 0</pose>
    	<inertial>
      	  <mass>10.0</mass>
          <inertia> <ixx>0.0416666666</ixx> 
	   	   <ixy>0.0</ixy> 
		   <ixz>0.0</ixz> 
		   <iyy>0.1416666666</iyy> 
		   <iyz>0.0</iyz>
		   <izz>0.1666666666</izz>
           </inertia>
        </inertial>
        <visual name='visual'>
          <pose frame=''> 0 0 0 -0 -0 -0 </pose>
          <geometry>
                <mesh>
                    <uri>file://model/body.STL</uri>
                    <scale>.1333 0.08 0.2</scale>
                </mesh>
          </geometry>
          <material>
            <script>
              <uri>file://media/materials/scripts/gazebo.material</uri>
              <name>Gazebo/Red</name>
            </script>
          </material>
          <transparency>0.2</transparency>
        </visual>

          <collision name='collision'>
            <geometry>
              <box>
                <size>.4 .2 .1</size>
              </box>
            </geometry>
          </collision>          
      </link>
   
       <link name='balance_stick'>
    	<inertial>
      	  <mass>1.0</mass>
          <inertia> <ixx>0.0133 </ixx> 
	   	   <ixy>0.0</ixy> 
		   <ixz>0.0</ixz> 
		   <iyy>0.0133</iyy> 
		   <iyz>0.0</iyz>
		   <izz>0.00001</izz>
           </inertia>
        </inertial>
          <pose>0 0 .35 0 0 0</pose>
        <collision name='collision'>
          <geometry>
              <box>
                <size>.01 .01 .4</size>
              </box>
          </geometry>
        </collision>
          <visual name='visual'>
          <geometry>
            <cylinder>
              <radius>0.01456</radius>
              <length>.4</length>
            </cylinder>
          </geometry>
          <material>
            <script>
              <uri>file://media/materials/scripts/gazebo.material</uri>
              <name>Gazebo/Green</name>
            </script>
          </material>
        </visual>
      </link>

      <link name="left_wheel">
        	<inertial>
      	  <mass>10.0</mass>
          <inertia> <ixx>0.02708333333</ixx> 
	   	   <ixy>0.0</ixy> 
		   <ixz>0.0</ixz> 
		   <iyy>0.02708333333</iyy> 
		   <iyz>0.0</iyz>
		   <izz>0.05</izz>
           </inertia>
        </inertial>
        <pose>0.17 0.13 0.05  0 -1.57079632679 -1.57079632679</pose>
        <collision name="collision">
          <geometry>
            <cylinder>
              <radius>.05</radius>
              <length>.05</length>
            </cylinder>
          </geometry>
        </collision>
        <visual name="visual">
          <geometry>
            <cylinder>
              <radius>.05</radius>
              <length>.05</length>
            </cylinder>
          </geometry>
            <transparency>0.4</transparency>
        </visual>
      </link>

     <link name="left_wheel_2">
        	<inertial>
      	  <mass>10.0</mass>
          <inertia> <ixx>0.02708333333</ixx> 
	   	   <ixy>0.0</ixy> 
		   <ixz>0.0</ixz> 
		   <iyy>0.02708333333</iyy> 
		   <iyz>0.0</iyz>
		   <izz>0.05</izz>
           </inertia>
        </inertial>
        <pose>-0.17 0.13 0.05  0 -1.57079632679 -1.57079632679</pose>
        <collision name="collision">
          <geometry>
            <cylinder>
              <radius>.05</radius>
              <length>.05</length>
            </cylinder>
          </geometry>
        </collision>
        <visual name="visual">
          <geometry>
            <cylinder>
              <radius>.05</radius>
              <length>.05</length>
            </cylinder>
          </geometry>
     <transparency>0.4</transparency>

        </visual>
      </link>

      <link name="right_wheel">
        	<inertial>
      	  <mass>10.0</mass>
          <inertia> <ixx>0.02708333333</ixx> 
	   	   <ixy>0.0</ixy> 
		   <ixz>0.0</ixz> 
		   <iyy>0.02708333333</iyy> 
		   <iyz>0.0</iyz>
		   <izz>0.05</izz>
           </inertia>
        </inertial>
        <pose>0.17 -0.13 0.05 0 -1.57079632679 -1.57079632679</pose>
        <collision name="collision">
          <geometry>
            <cylinder>
              <radius>0.05</radius>
              <length>0.05</length>
            </cylinder>
          </geometry>
        </collision>
        <visual name="visual">
          <geometry>
            <cylinder>
              <radius>0.05</radius>
              <length>0.05</length>
            </cylinder>
          </geometry>
     <transparency>0.4</transparency>
        </visual>
      </link>


      <link name="right_wheel_2">
        	<inertial>
      	  <mass>10.0</mass>
          <inertia> <ixx>0.02708333333</ixx> 
	   	   <ixy>0.0</ixy> 
		   <ixz>0.0</ixz> 
		   <iyy>0.02708333333</iyy> 
		   <iyz>0.0</iyz>
		   <izz>0.05</izz>
           </inertia>
        </inertial>
        <pose>-0.17 -0.13 0.05 0 -1.57079632679 -1.57079632679</pose>
        <collision name="collision">
          <geometry>
            <cylinder>
              <radius>.05</radius>
              <length>.05</length>
            </cylinder>
          </geometry>
        </collision>
        <visual name="visual">
          <geometry>
            <cylinder>
              <radius>.05</radius>
              <length>.05</length>
            </cylinder>
          </geometry>
        <transparency>0.4</transparency>
        </visual>
      </link>

      <joint type="revolute" name="left_wheel_hinge">
        <child>left_wheel</child>
        <parent>cart_body</parent>
        <axis>
          <xyz>0 0 1</xyz>
        </axis>
      </joint>

      <joint type="revolute" name="right_wheel_hinge">
        <child>right_wheel</child>
        <parent>cart_body</parent>
        <axis>
          <xyz>0 0 1</xyz>
        </axis>
      </joint>

      <joint type="revolute" name="left_wheel_hinge_2">
        <child>left_wheel_2</child>
        <parent>cart_body</parent>
        <axis>
          <xyz>0 0 1</xyz>
        </axis>
      </joint>

      <joint type="revolute" name="right_wheel_hinge_2">
        <child>right_wheel_2</child>
        <parent>cart_body</parent>
        <axis>
          <xyz>0 0 1</xyz>
        </axis>
      </joint>

      <joint name='pendulum_pivot' type='revolute'>
        <parent>cart_body</parent>
        <child>balance_stick</child>
        <pose frame=''>0 0 -0.2 0 -0 0</pose>
        <axis>
          <xyz>0 1 0</xyz>
        </axis>
      </joint>


    </model>
  </world>
</sdf>


